Workbook

Sheet Sheet1
A1: Product Feature | B1: Material | C1: Supplier | D1: Estimated Units | E1: Unit Cost | F1: Total COGS | G1: Notes
A2: Eco Battery | B2: Aluminum | C2: Adatum Corporation | D2: 845 | E2: 23.51 | F2: 19865.95
A3: Energy Sensor | B3: Glass | C3: Boulder Innovations | D3: 1838 | E3: 83.38 | F3: 153252.44 | G3: Urgent review required
A4: Solar Panel | B4: Copper | C4: Contoso, Ltd. | D4: 401 | E4: 79.88 | F4: 32031.88 | G4: Bulk discount applied
A5: Eco Battery | B5: Silicon | C5: VanArsdel, Ltd. | D5: 4033 | E5: 68.08 | F5: 274566.64 | G5: Urgent review required
A6: Eco Battery | B6: Copper | C6: VanArsdel, Ltd. | D6: 135 | E6: 12.22 | F6: 1649.7 | G6: Check supplier pricing
A7: Energy Sensor | B7: Steel | C7: VanArsdel, Ltd. | D7: 1410 | E7: 114.82 | F7: 161896.2 | G7: Check supplier pricing
A8: Solar Panel | B8: Composite | C8: VanArsdel, Ltd. | D8: 3456 | E8: 32.96 | F8: 113909.76 | G8: Check supplier pricing
A9: Smart Charger | B9: Aluminum | C9: Boulder Innovations | D9: 4014 | E9: 68.98 | F9: 276885.72 | G9: Check supplier pricing
A10: Recycled Frame | B10: Steel | C10: VanArsdel, Ltd. | D10: 4344 | E10: 122.04 | F10: 530141.76 | G10: Urgent review required | K10: 0937628_lodsprod
A11: Solar Panel | B11: Composite | C11: Contoso, Ltd. | D11: 2102 | E11: 10.44 | F11: 21944.88 | G11: Bulk discount applied
A12: Smart Thermostat | B12: Glass | C12: VanArsdel, Ltd. | D12: 488 | E12: 132.43 | F12: 64625.84 | G12: Check supplier pricing
A13: Recycled Frame | B13: Composite | C13: Adatum Corporation | D13: 1943 | E13: 12.22 | F13: 23743.46 | G13: Bulk discount applied
A14: Smart Charger | B14: Copper | C14: VanArsdel, Ltd. | D14: 3775 | E14: 140.77 | F14: 531406.75 | G14: Bulk discount applied
A15: Solar Panel | B15: Steel | C15: Northwind Traders | D15: 2465 | E15: 84.27 | F15: 207725.55 | G15: Bulk discount applied
A16: Smart Charger | B16: Lithium | D16: 4547 | E16: 55.78 | F16: 253631.66 | G16: Check supplier pricing
A17: Energy Sensor | B17: Aluminum | C17: Trey Research | D17: 2918 | E17: 652.6 | F17: 245432.98 | G17: Bulk discount applied
A18: Energy Sensor | B18: Steel | C18: Trey Research | D18: 2821 | E18: 55.22 | F18: 155775.62
A19: LED Display | B19: Steel | C19: VanArsdel, Ltd. | D19: 3830 | E19: 21.19 | F19: 81157.7 | G19: Urgent review required
A20: Solar Panel | B20: Lithium | C20: Northwind Traders | D20: 4732 | E20: 61.98 | F20: 293289.36 | G20: Check supplier pricing
A21: Recycled Frame | B21: Lithium | C21: Boulder Innovations | D21: 4749 | E21: 9.8 | F21: 46540.2
A22: Recycled Frame | B22: Steel | C22: Boulder Innovations | D22: 3966 | E22: 142.47 | F22: 565036.02
A23: Smart Charger | B23: Glass | D23: 1514 | E23: 112.53 | F23: 170370.42 | G23: Urgent review required
A24: Smart Thermostat | B24: Plastic | C24: Trey Research | D24: 2006 | E24: 732.82 | F24: 109748.26 | G24: Bulk discount applied
A25: Solar Panel | B25: Silicon | C25: Adatum Corporation | D25: 2666 | E25: 85.32 | F25: 227463.12
A26: Smart Thermostat | B26: Lithium | C26: Contoso, Ltd. | D26: 1096 | E26: 115.79 | F26: 126905.84 | G26: Urgent review required
A27: Water Filter | B27: Copper | C27: Trey Research | D27: 4734 | E27: 143.45 | F27: 679092.3
A28: LED Display | B28: Aluminum | C28: VanArsdel, Ltd. | D28: 1800 | E28: 892.75 | F28: 126882
A29: Energy Sensor | B29: Glass | C29: Contoso, Ltd. | D29: 1623 | E29: 92.41 | F29: 149981.43
A30: Solar Panel | B30: Lithium | C30: Trey Research | D30: 2439 | E30: 148.69 | F30: 362654.91 | G30: Check supplier pricing
A31: LED Display | B31: Copper | C31: Adatum Corporation | D31: 1376 | E31: 74.37 | F31: 102333.12
A32: Energy Sensor | B32: Copper | C32: Boulder Innovations | D32: 321 | E32: 84.13 | F32: 27005.73
A33: Water Filter | B33: Steel | C33: Boulder Innovations | D33: 2417 | E33: 12.22 | F33: 29535.74
A34: Recycled Frame | B34: Composite | C34: Trey Research | D34: 324 | E34: 80.83 | F34: 26188.92 | G34: Urgent review required
A35: Recycled Frame | B35: Aluminum | C35: VanArsdel, Ltd. | D35: 3835 | E35: 19.64 | F35: 75319.4 | G35: Bulk discount applied
A36: Water Filter | B36: Glass | C36: Contoso, Ltd. | D36: 2883 | E36: 43.46 | F36: 125295.18 | G36: Check supplier pricing
A37: Energy Sensor | B37: Glass | C37: Contoso, Ltd. | D37: 3494 | E37: 125.91 | F37: 439929.54 | G37: Bulk discount applied
A38: Water Filter | B38: Aluminum | C38: Boulder Innovations | D38: 4943 | E38: 109.65 | F38: 541999.95
A39: Smart Charger | B39: Glass | C39: Contoso, Ltd. | D39: 1279 | E39: 48.69 | F39: 62274.51 | G39: Bulk discount applied
A40: Recycled Frame | B40: Composite | C40: Contoso, Ltd. | D40: 3846 | E40: 77.56 | F40: 298295.76 | G40: Bulk discount applied
...

Sheet Data Analysis
A1: SECTION 1: Column Descriptions
A3: Column Name | B3: Data Type | C3: Description & Purpose
A4: Product Feature | B4: Text | C4: Name of the product component in the ZavaHome line (e.g., Eco Battery, Solar Panel, Smart Charger)
A5: Material | B5: Text | C5: Primary material used in manufacturing (e.g., Aluminum, Copper, Silicon, Glass, Steel)
A6: Supplier | B6: Text | C6: Vendor/company supplying the component (e.g., Contoso, Ltd., VanArsdel, Ltd., Trey Research)
A7: Estimated Units | B7: Numeric (Integer) | C7: Projected quantity of units to be ordered/produced for cost estimation
A8: Unit Cost | B8: Currency ($) | C8: Cost per individual unit from the supplier, used for COGS calculation
A9: Total COGS | B9: Currency ($) | C9: Total Cost of Goods Sold = Estimated Units × Unit Cost; key metric for financial planning
A10: Notes | B10: Text | C10: Flags for action items: pricing reviews, bulk discounts applied, or urgent reviews needed
A13: SECTION 2: Data Quality Issues Identified
A15: Issue Type | B15: Location | C15: Details | D15: Impact on Accuracy
A16: Missing Supplier | B16: Row 16 (C16) | C16: Smart Charger - Lithium has no supplier listed | D16: Cannot verify pricing or procurement source; affects supplier spend analysis
A17: Missing Supplier | B17: Row 23 (C23) | C17: Smart Charger - Glass has no supplier listed | D17: Cannot verify pricing or procurement source; affects supplier spend analysis
A18: Potential Unit Cost Outlier | B18: Row 17 (E17) | C18: Energy Sensor - Aluminum: Unit Cost = $652.60 | D18: Significantly higher than similar products; may be data entry error or premium component
A19: Potential Unit Cost Outlier | B19: Row 24 (E24) | C19: Smart Thermostat - Plastic: Unit Cost = $732.82 | D19: Unusually high for plastic material; verify with supplier quote
A20: Potential Unit Cost Outlier | B20: Row 28 (E28) | C20: LED Display - Aluminum: Unit Cost = $892.75 | D20: Highest unit cost in dataset; needs verification against supplier contracts
A21: Empty Notes Field | B21: Multiple Rows | C21: Rows 2, 18, 21, 22, 25, 27, 28, 31, 32, 33, 38, 47 have no notes | D21: May indicate missing review status or action items; consider standardizing
A22: Inconsistent Notes Categories | B22: Column G | C22: Mix of: 'Urgent review required', 'Bulk discount applied', 'Check supplier pricing', and blanks | D22: Recommend standardized status codes for better filtering and tracking
A25: SECTION 3: Quick Data Summary (Formula-Based)
A27: Metric | B27: Value
A28: Total Records | B28: =COUNTA(Sheet1!A2:A51) -> 50
A29: Unique Product Features | B29: {=SUMPRODUCT(1/COUNTIF(Sheet1!A2:A51,Sheet1!A2:A51))} -> 8
A30: Unique Suppliers (non-blank) | B30: {=SUMPRODUCT((Sheet1!C2:C51<>"")/COUNTIF(Sheet1!C2:C51,Sheet1!C2:C51&""))} -> 6
A31: Missing Supplier Count | B31: =COUNTBLANK(Sheet1!C2:C51) -> 2
A32: Total Estimated Units | B32: =SUM(Sheet1!D2:D51) -> 132124
A33: Total COGS | B33: =SUM(Sheet1!F2:F51) -> 10895444
A34: Average Unit Cost | B34: =AVERAGE(Sheet1!E2:E51) -> 120.6744
A35: Max Unit Cost | B35: =MAX(Sheet1!E2:E51) -> 892.75
A36: Min Unit Cost | B36: =MIN(Sheet1!E2:E51) -> 9.8
A37: Records Needing Urgent Review | B37: =COUNTIF(Sheet1!G2:G51,"*Urgent*") -> 11
A38: Records with Bulk Discount | B38: =COUNTIF(Sheet1!G2:G51,"*Bulk*") -> 14
A39: Records to Check Pricing | B39: =COUNTIF(Sheet1!G2:G51,"*Check*") -> 12

Sheet COGS Review
A1: Zava Home COGS Estimates — Data Review
A2: Purpose: document key fields and flag missing or inconsistent data points that could affect COGS accuracy.
A4: 1) Key Column Descriptions
A5: Column | B5: Data Type | C5: Purpose | D5: Accuracy Consideration
A6: Product Feature | B6: Text | C6: Identifies the Zava Home component being costed. | D6: Needed for product-level COGS aggregation and variance review.
A7: Material | B7: Text | C7: Primary material used in the component. | D7: Supports material cost benchmarking and outlier checks.
A8: Supplier | B8: Text | C8: Vendor providing the component/material. | D8: Required for supplier spend analysis and quote validation.
A9: Estimated Units | B9: Integer | C9: Projected number of units to order or produce. | D9: Key volume driver for Total COGS; incorrect values distort totals.
A10: Unit Cost | B10: Currency | C10: Estimated cost per unit from supplier quote or assumption. | D10: Primary cost assumption; outliers should be verified.
A11: Total COGS | B11: Currency | C11: Extended cost for each line item. | D11: Should equal Estimated Units × Unit Cost.
A12: Notes | B12: Text / Status | C12: Action or review flag such as urgent review, bulk discount, or pricing check. | D12: Blank or inconsistent statuses make follow-up prioritization harder.
A15: 2) Missing or Inconsistent Data Points Affecting Accuracy
A16: Issue | B16: Location | C16: Details | D16: Potential Impact / Recommended Action
A17: Missing supplier | B17: Sheet1!C16 | C17: Smart Charger / Lithium has no supplier listed. | D17: Cannot validate source pricing or include accurately in supplier spend analysis; request supplier name.
A18: Missing supplier | B18: Sheet1!C23 | C18: Smart Charger / Glass has no supplier listed. | D18: Cannot validate source pricing or include accurately in supplier spend analysis; request supplier name.
A19: Total COGS formula mismatch | B19: Sheet1!F17 | C19: Reported $245,432.98 vs expected $1,904,286.80 from 2,918 × $652.60. | D19: Material understatement of $1,658,853.82 if Unit Cost is correct; verify Unit Cost and Total COGS.
A20: Total COGS formula mismatch | B20: Sheet1!F24 | C20: Reported $109,748.26 vs expected $1,470,036.92 from 2,006 × $732.82. | D20: Material understatement of $1,360,288.66 if Unit Cost is correct; verify Unit Cost and Total COGS.
A21: Total COGS formula mismatch | B21: Sheet1!F28 | C21: Reported $126,882.00 vs expected $1,606,950.00 from 1,800 × $892.75. | D21: Material understatement of $1,480,068.00 if Unit Cost is correct; verify Unit Cost and Total COGS.
A22: Potential unit cost outlier | B22: Sheet1!E17, E24, E28 | C22: Unit costs of $652.60, $732.82, and $892.75 are materially higher than most records. | D22: These rows also drive COGS mismatches; confirm whether decimals or totals were entered incorrectly.
A23: Blank notes/status | B23: Rows 2, 18, 21, 22, 25, 27, 28, 29, 31, 32, 33, 38, 47 | C23: 13 records have no review status or action note. | D23: May hide unresolved pricing/review actions; standardize a required status value.
A24: Inconsistent notes categories | B24: Sheet1!G:G | C24: Notes mix action items, discount indicators, urgent review flags, and blanks. | D24: Harder to filter by workflow state; consider controlled status categories.
A25: Unexpected data outside table | B25: Sheet1!K10 | C25: Value “0937628_lodsprod” appears outside the main A:G dataset. | D25: May be stray metadata or pasted value; remove or document if relevant.
A29: Summary Metrics
A30: Metric | B30: Value | C30: Formula / Basis | D30: Comment
A31: Total records | B31: =COUNTA(Sheet1!A2:A51) -> 50 | C31: COUNTA(Product Feature) | D31: Full dataset reviewed.
A32: Missing supplier count | B32: =COUNTBLANK(Sheet1!C2:C51) -> 2 | C32: COUNTBLANK(Supplier) | D32: Two records require supplier follow-up.
A33: Blank notes count | B33: =COUNTBLANK(Sheet1!G2:G51) -> 13 | C33: COUNTBLANK(Notes) | D33: 13 records need status standardization.
A34: COGS formula mismatches | B34: {=SUMPRODUCT(--(ROUND(Sheet1!D2:D51*Sheet1!E2:E51,2)<>ROUND(Sheet1!F2:F51,2)))} -> 3 | C34: Estimated Units × Unit Cost vs Total COGS | D34: Three records have material calculation inconsistencies.
A35: Max unit cost | B35: =MAX(Sheet1!E2:E51) -> 892.75 | C35: MAX(Unit Cost) | D35: Used to identify top outlier.
A36: Total COGS as reported | B36: =SUM(Sheet1!F2:F51) -> 10895444 | C36: SUM(Total COGS) | D36: Core forecast total before corrections.

Sheet COGS Analysis Report
A1: Zava Home COGS Estimates — Data Review Report
A2: Purpose: Document key fields and flag missing or inconsistent data points that could affect COGS accuracy.
A4: SECTION 1: Key Column Descriptions
A5: Column | B5: Data Type | C5: Purpose | D5: Accuracy Consideration
A6: Product Feature | B6: Text | C6: Identifies the Zava Home component being costed (e.g., Eco Battery, Solar Panel). | D6: Needed for product-level COGS aggregation and variance review.
A7: Material | B7: Text | C7: Primary material used in the component (e.g., Aluminum, Copper, Silicon). | D7: Supports material cost benchmarking and outlier checks.
A8: Supplier | B8: Text | C8: Vendor providing the component/material (e.g., Contoso, Ltd., VanArsdel, Ltd.). | D8: Required for supplier spend analysis and quote validation.
A9: Estimated Units | B9: Integer | C9: Projected number of units to order or produce. | D9: Key volume driver for Total COGS; incorrect values distort totals.
A10: Unit Cost | B10: Currency ($) | C10: Estimated cost per unit from supplier quote or assumption. | D10: Primary cost assumption; outliers should be verified.
A11: Total COGS | B11: Currency ($) | C11: Extended cost for each line item (Estimated Units × Unit Cost). | D11: Should equal Estimated Units × Unit Cost; mismatches indicate errors.
A12: Notes | B12: Text / Status | C12: Action or review flag (e.g., urgent review, bulk discount, pricing check). | D12: Blank or inconsistent statuses make follow-up prioritization harder.
A14: SECTION 2: Missing or Inconsistent Data Points Affecting Accuracy
A15: Issue Type | B15: Location | C15: Details | D15: Impact / Recommended Action
A16: Missing Supplier | B16: Sheet1!C16 | C16: Smart Charger / Lithium has no supplier listed. | D16: Cannot validate source pricing; request supplier name.
A17: Missing Supplier | B17: Sheet1!C23 | C17: Smart Charger / Glass has no supplier listed. | D17: Cannot validate source pricing; request supplier name.
A18: COGS Formula Mismatch | B18: Sheet1!F17 | C18: Reported $245,433 vs expected $1,904,287 (2,918 × $652.60). | D18: Understatement of $1,658,854; verify Unit Cost and formula.
A19: COGS Formula Mismatch | B19: Sheet1!F24 | C19: Reported $109,748 vs expected $1,470,037 (2,006 × $732.82). | D19: Understatement of $1,360,289; verify Unit Cost and formula.
A20: COGS Formula Mismatch | B20: Sheet1!F28 | C20: Reported $126,882 vs expected $1,606,950 (1,800 × $892.75). | D20: Understatement of $1,480,068; verify Unit Cost and formula.
A21: Unit Cost Outlier | B21: Sheet1!E17 | C21: Energy Sensor / Aluminum: Unit Cost = $652.60. | D21: 10x+ higher than similar products; confirm accuracy.
A22: Unit Cost Outlier | B22: Sheet1!E24 | C22: Smart Thermostat / Plastic: Unit Cost = $732.82. | D22: Unusually high for plastic; verify against supplier quote.
A23: Unit Cost Outlier | B23: Sheet1!E28 | C23: LED Display / Aluminum: Unit Cost = $892.75. | D23: Highest unit cost in dataset; verify against contracts.
A24: Blank Notes/Status | B24: Sheet1!G (13 rows) | C24: Rows 2,18,21,22,25,27,28,31,32,33,38,47 have no status. | D24: May hide unresolved actions; standardize status values.
A25: Inconsistent Notes | B25: Sheet1!G:G | C25: Notes mix action items, discount flags, and review flags. | D25: Harder to filter by workflow; use controlled categories.
A26: Stray Data | B26: Sheet1!K10 | C26: Value '0937628_lodsprod' outside main A:G dataset. | D26: Remove or document if relevant metadata.
A28: SECTION 3: Summary Metrics (Formula-Based)
A29: Metric | B29: Value | C29: Formula / Basis
A30: Total Records | B30: =COUNTA(Sheet1!A2:A51) -> 50 | C30: COUNTA of Product Feature column
A31: Unique Product Features | B31: {=SUMPRODUCT(1/COUNTIF(Sheet1!A2:A51,Sheet1!A2:A51))} -> 8 | C31: Count of unique product names
A32: Unique Suppliers (non-blank) | B32: {=SUMPRODUCT((Sheet1!C2:C51<>"")*(1/COUNTIF(Sheet1!C2:C51,Sheet1!C2:C51&"")))} -> 6 | C32: Count of unique suppliers (excluding blanks)
A33: Missing Supplier Count | B33: =COUNTBLANK(Sheet1!C2:C51) -> 2 | C33: COUNTBLANK of Supplier column
A34: Total Estimated Units | B34: =SUM(Sheet1!D2:D51) -> 132124 | C34: SUM of Estimated Units
A35: Total COGS (as reported) | B35: =SUM(Sheet1!F2:F51) -> 10895444 | C35: SUM of Total COGS column
A36: Average Unit Cost | B36: =AVERAGE(Sheet1!E2:E51) -> 120.6744 | C36: AVERAGE of Unit Cost column
A37: Max Unit Cost | B37: =MAX(Sheet1!E2:E51) -> 892.75 | C37: MAX of Unit Cost column
A38: Min Unit Cost | B38: =MIN(Sheet1!E2:E51) -> 9.8 | C38: MIN of Unit Cost column
A39: Records Needing Urgent Review | B39: =COUNTIF(Sheet1!G2:G51,"Urgent review required") -> 11 | C39: COUNTIF for 'Urgent review required'
A40: Records with Bulk Discount | B40: =COUNTIF(Sheet1!G2:G51,"Bulk discount applied") -> 14 | C40: COUNTIF for 'Bulk discount applied'
A41: Records to Check Pricing | B41: =COUNTIF(Sheet1!G2:G51,"Check supplier pricing") -> 12 | C41: COUNTIF for 'Check supplier pricing'

Sheet Data Review Summary
A1: I'm a financial analyst for Zava Retail. I was asked to analyze
A2: the Zava Home COGS Estimates spreadsheet for Zava Retail's new Zava
A3: Home product line. Can you please review the dataset in this
A4: spreadsheet and provide two things in a new sheet: (1) a clear
A5: description of each key column and its purpose, and (2) a list of any | B5: Data Type | C5: Purpose | D5: Accuracy Consideration
A6: missing or inconsistent data points that could affect accuracy. | B6: Text | C6: Identifies the Zava Home component being costed (e.g., Eco Battery, Solar Panel, Smart Charger). | D6: Required for product-level COGS aggregation and variance analysis.
A7: Present your findings in a concise, structured format in a new sheet. | B7: Text | C7: Primary material used in the component (e.g., Aluminum, Copper, Silicon, Glass). | D7: Supports material cost benchmarking and outlier detection.
A8: Supplier | B8: Text | C8: Vendor providing the component/material (e.g., Contoso, Ltd., VanArsdel, Ltd.). | D8: Required for supplier spend analysis and quote validation.
A9: Estimated Units | B9: Integer | C9: Projected number of units to order or produce. | D9: Key volume driver for Total COGS; incorrect values distort totals.
A10: Unit Cost | B10: Currency ($) | C10: Estimated cost per unit from supplier quote or assumption. | D10: Primary cost assumption; outliers should be verified against contracts.
A11: Total COGS | B11: Currency ($) | C11: Extended cost for each line item (should equal Estimated Units × Unit Cost). | D11: Mismatches indicate calculation errors requiring correction.
A12: Notes | B12: Text / Status | C12: Action or review flags (e.g., Urgent review, Bulk discount, Check pricing). | D12: Blank or inconsistent statuses make follow-up prioritization difficult.
A14: SECTION 2: Missing or Inconsistent Data Points Affecting Accuracy
A15: Issue Type | B15: Location | C15: Details | D15: Impact / Recommended Action
A16: Missing Supplier | B16: Sheet1!C16 | C16: Smart Charger / Lithium has no supplier listed. | D16: Cannot validate pricing; request supplier name.
A17: Missing Supplier | B17: Sheet1!C23 | C17: Smart Charger / Glass has no supplier listed. | D17: Cannot validate pricing; request supplier name.
A18: COGS Formula Mismatch | B18: Sheet1!F17 | C18: Reported $245,433 vs expected $1,904,287 (2,918 × $652.60). | D18: Understatement of ~$1.66M; verify Unit Cost and recalculate.
A19: COGS Formula Mismatch | B19: Sheet1!F24 | C19: Reported $109,748 vs expected $1,470,037 (2,006 × $732.82). | D19: Understatement of ~$1.36M; verify Unit Cost and recalculate.
A20: COGS Formula Mismatch | B20: Sheet1!F28 | C20: Reported $126,882 vs expected $1,606,950 (1,800 × $892.75). | D20: Understatement of ~$1.48M; verify Unit Cost and recalculate.
A21: Unit Cost Outlier | B21: Sheet1!E17, E24, E28 | C21: Unit costs of $652.60, $732.82, $892.75 are 5-10x higher than typical. | D21: May be data entry error; verify with supplier quotes.
A22: Blank Notes/Status | B22: Sheet1!G (13 rows) | C22: Rows 2, 18, 21, 22, 25, 27, 28, 31, 32, 33, 38, 47 have no status. | D22: May hide unresolved actions; standardize status values.
A23: Inconsistent Notes | B23: Sheet1!G:G | C23: Notes mix action items, discount indicators, and review flags. | D23: Harder to filter; consider controlled status categories.
A24: Stray Data | B24: Sheet1!K10 | C24: Value '0937628_lodsprod' outside main A:G dataset. | D24: Remove or document if relevant metadata.
A26: SECTION 3: Summary Metrics
A27: Metric | B27: Value | C27: Formula / Basis
A28: Total Records | B28: =COUNTA(Sheet1!A2:A51) -> 50 | C28: COUNTA of Product Feature column
A29: Missing Supplier Count | B29: =COUNTBLANK(Sheet1!C2:C51) -> 2 | C29: COUNTBLANK of Supplier column
A30: Blank Notes Count | B30: =COUNTBLANK(Sheet1!G2:G51) -> 13 | C30: COUNTBLANK of Notes column
A31: COGS Formula Mismatches | B31: 3 | C31: Manual count where Units × Cost ≠ Total COGS
A32: Total COGS (as reported) | B32: =SUM(Sheet1!F2:F51) -> 10895444 | C32: SUM of Total COGS column
A33: Max Unit Cost | B33: =MAX(Sheet1!E2:E51) -> 892.75 | C33: MAX of Unit Cost column
A34: Min Unit Cost | B34: =MIN(Sheet1!E2:E51) -> 9.8 | C34: MIN of Unit Cost column

Sheet COGS Data Review

Sheet Data Quality Review
A1: Zava Home COGS Estimates — Data Review
A2: Purpose: Document key fields and identify data quality issues affecting COGS accuracy.
A4: SECTION 1: Key Column Descriptions
A5: Column | B5: Data Type | C5: Purpose | D5: Accuracy Consideration
A6: Product Feature | B6: Text | C6: Identifies the Zava Home component being costed (e.g., Eco Battery, Solar Panel, Smart Charger). | D6: Required for product-level COGS aggregation and variance analysis.
A7: Material | B7: Text | C7: Primary material used in manufacturing (e.g., Aluminum, Copper, Silicon, Glass). | D7: Supports material cost benchmarking and outlier detection.
A8: Supplier | B8: Text | C8: Vendor providing the component (e.g., Contoso, Ltd., VanArsdel, Ltd., Trey Research). | D8: Required for supplier spend analysis and quote validation.
A9: Estimated Units | B9: Integer | C9: Projected number of units to order or produce. | D9: Key volume driver for Total COGS; incorrect values distort totals.
A10: Unit Cost | B10: Currency ($) | C10: Estimated cost per unit from supplier quote or assumption. | D10: Primary cost assumption; outliers should be verified against contracts.
A11: Total COGS | B11: Currency ($) | C11: Extended cost for each line item (should equal Estimated Units × Unit Cost). | D11: Mismatches indicate calculation errors requiring correction.
A12: Notes | B12: Text / Status | C12: Action or review flags (e.g., Urgent review, Bulk discount, Check pricing). | D12: Blank or inconsistent statuses make follow-up prioritization difficult.

Sheet COGS Review Report
A1: Zava Home COGS Estimates — Data Review
A2: Purpose: Document key fields and identify data quality issues affecting COGS accuracy.
A4: SECTION 1: Key Column Descriptions
A5: Column | B5: Data Type | C5: Purpose | D5: Accuracy Consideration
A6: Product Feature | B6: Text | C6: Identifies the Zava Home component being costed (e.g., Eco Battery, Solar Panel). | D6: Required for product-level COGS aggregation.
A7: Material | B7: Text | C7: Primary material used in manufacturing (e.g., Aluminum, Copper, Silicon). | D7: Supports material cost benchmarking.
A8: Supplier | B8: Text | C8: Vendor providing the component (e.g., Contoso, Ltd., VanArsdel, Ltd.). | D8: Required for supplier spend analysis.
A9: Estimated Units | B9: Integer | C9: Projected number of units to order or produce. | D9: Key volume driver for Total COGS.
A10: Unit Cost | B10: Currency ($) | C10: Estimated cost per unit from supplier quote. | D10: Outliers should be verified against contracts.
A11: Total COGS | B11: Currency ($) | C11: Extended cost (should equal Units × Unit Cost). | D11: Mismatches indicate calculation errors.
A12: Notes | B12: Text / Status | C12: Action or review flags (Urgent review, Bulk discount, etc.). | D12: Blank statuses make follow-up difficult.
A14: SECTION 2: Missing or Inconsistent Data Points
A15: Issue Type | B15: Location | C15: Details | D15: Impact / Action
A16: Missing Supplier | B16: Sheet1!C16 | C16: Smart Charger / Lithium - no supplier | D16: Request supplier name
A17: Missing Supplier | B17: Sheet1!C23 | C17: Smart Charger / Glass - no supplier | D17: Request supplier name
A18: COGS Mismatch | B18: Sheet1!F17 | C18: Row 17: Expected $1,904,287 vs $245,433 | D18: Verify Unit Cost; recalculate
A19: COGS Mismatch | B19: Sheet1!F24 | C19: Row 24: Expected $1,470,037 vs $109,748 | D19: Verify Unit Cost; recalculate
A20: COGS Mismatch | B20: Sheet1!F28 | C20: Row 28: Expected $1,606,950 vs $126,882 | D20: Verify Unit Cost; recalculate
A21: Unit Cost Outlier | B21: E17, E24, E28 | C21: $652.60, $732.82, $892.75 (5-10× typical) | D21: Verify with supplier quotes
A22: Blank Notes | B22: Column G | C22: 13 rows have no status/notes | D22: Standardize status values
A23: Inconsistent Notes | B23: Column G | C23: Mix of action items, discounts, flags | D23: Use controlled categories
A24: Stray Data | B24: Sheet1!K10 | C24: 0937628_lodsprod' outside dataset | D24: Remove or document
A26: SECTION 3: Summary Metrics (Formula-Based)
A27: Metric | B27: Value | C27: Formula
A28: Total Records | B28: =COUNTA(Sheet1!A2:A51) -> 50
A29: Missing Supplier Count | B29: =COUNTBLANK(Sheet1!C2:C51) -> 2
A30: Blank Notes Count | B30: =COUNTBLANK(Sheet1!G2:G51) -> 13
A31: Total COGS (as reported) | B31: =SUM(Sheet1!F2:F51) -> 10895444
A32: Total Estimated Units | B32: =SUM(Sheet1!D2:D51) -> 132124
A33: Average Unit Cost | B33: =AVERAGE(Sheet1!E2:E51) -> 120.6744
A34: Max Unit Cost | B34: =MAX(Sheet1!E2:E51) -> 892.75
A35: Min Unit Cost | B35: =MIN(Sheet1!E2:E51) -> 9.8
A36: Urgent Review Count | B36: =COUNTIF(Sheet1!G2:G51,"Urgent review required") -> 11
A37: COGS Mismatches | B37: {=SUMPRODUCT((ROUND(Sheet1!D2:D51*Sheet1!E2:E51,2)<>Sheet1!F2:F51)*1)} -> 3

Sheet COGS Quality Review
A1: Zava Home COGS Estimates — Data Review
A2: Purpose: Document key fields and identify data quality issues affecting COGS accuracy.
A4: SECTION 1: Key Column Descriptions
A5: Column | B5: Data Type | C5: Purpose | D5: Accuracy Consideration
A6: Product Feature | B6: Text | C6: Identifies the Zava Home component being costed. | D6: Required for product-level COGS aggregation.
A7: Material | B7: Text | C7: Primary material used in manufacturing. | D7: Supports material cost benchmarking.
A8: Supplier | B8: Text | C8: Vendor providing the component. | D8: Required for supplier spend analysis.
A9: Estimated Units | B9: Integer | C9: Projected number of units to order. | D9: Key volume driver for Total COGS.
A10: Unit Cost | B10: Currency ($) | C10: Estimated cost per unit from supplier. | D10: Outliers should be verified.
A11: Total COGS | B11: Currency ($) | C11: Extended cost (Units × Unit Cost). | D11: Mismatches indicate errors.
A12: Notes | B12: Text / Status | C12: Action or review flags. | D12: Blank statuses make follow-up difficult.
A14: SECTION 2: Missing or Inconsistent Data Points
A15: Issue Type | B15: Location | C15: Details | D15: Impact / Action
A16: Missing Supplier | B16: Sheet1!C16 | C16: Smart Charger / Lithium - no supplier | D16: Request supplier name
A17: Missing Supplier | B17: Sheet1!C23 | C17: Smart Charger / Glass - no supplier | D17: Request supplier name
A18: COGS Mismatch | B18: Sheet1!F17 | C18: ="Expected $"&TEXT(Sheet1!D17*Sheet1!E17,"#,##0.00")&" vs Actual $"&TEXT(Sheet1!F17,"#,##0.00") -> Expected $1,904,286.80 vs Actual $245,432.98 | D18: Verify and recalculate
A19: COGS Mismatch | B19: Sheet1!F24 | C19: ="Expected $"&TEXT(Sheet1!D24*Sheet1!E24,"#,##0.00")&" vs Actual $"&TEXT(Sheet1!F24,"#,##0.00") -> Expected $1,470,036.92 vs Actual $109,748.26 | D19: Verify and recalculate
A20: COGS Mismatch | B20: Sheet1!F28 | C20: ="Expected $"&TEXT(Sheet1!D28*Sheet1!E28,"#,##0.00")&" vs Actual $"&TEXT(Sheet1!F28,"#,##0.00") -> Expected $1,606,950.00 vs Actual $126,882.00 | D20: Verify and recalculate
A21: Unit Cost Outlier | B21: E17, E24, E28 | C21: $652-$893 (5-10× typical) | D21: Verify with supplier quotes
A22: Blank Notes | B22: Column G | C22: 13 rows have no status | D22: Standardize status values
A23: Inconsistent Notes | B23: Column G | C23: Mix of action items and flags | D23: Use controlled categories
A24: Stray Data | B24: Sheet1!K10 | C24: Data outside main dataset | D24: Remove or document
A26: SECTION 3: Summary Metrics (Formula-Based)
A27: Metric | B27: Value | C27: Formula
A28: Total Records | B28: =COUNTA(Sheet1!A2:A51) -> 50 | C28: =COUNTA(Sheet1!A2:A51) -> 50
A29: Missing Supplier Count | B29: =COUNTBLANK(Sheet1!C2:C51) -> 2 | C29: =COUNTBLANK(Sheet1!C2:C51) -> 2
A30: Blank Notes Count | B30: =COUNTBLANK(Sheet1!G2:G51) -> 13 | C30: =COUNTBLANK(Sheet1!G2:G51) -> 13
A31: Total COGS (as reported) | B31: =SUM(Sheet1!F2:F51) -> 10895444 | C31: =SUM(Sheet1!F2:F51) -> 10895444
A32: Total Estimated Units | B32: =SUM(Sheet1!D2:D51) -> 132124 | C32: =SUM(Sheet1!D2:D51) -> 132124
A33: Average Unit Cost | B33: =AVERAGE(Sheet1!E2:E51) -> 120.6744 | C33: =AVERAGE(Sheet1!E2:E51) -> 120.6744
A34: Max Unit Cost | B34: =MAX(Sheet1!E2:E51) -> 892.75 | C34: =MAX(Sheet1!E2:E51) -> 892.75
A35: Min Unit Cost | B35: =MIN(Sheet1!E2:E51) -> 9.8 | C35: =MIN(Sheet1!E2:E51) -> 9.8
A36: Urgent Review Count | B36: =COUNTIF(Sheet1!G2:G51,"Urgent review required") -> 11 | C36: COUNTIF for 'Urgent review'
A37: COGS Mismatches | B37: {=SUMPRODUCT((ROUND(Sheet1!D2:D51*Sheet1!E2:E51,2)<>Sheet1!F2:F51)*1)} -> 3 | C37: SUMPRODUCT mismatch check
